<?xml version='1.0'?>

<sdf version='1.6'>
	<model name='Herramienta'>
		<self_collide>false</self_collide>
		<link name='parte_fija'>
			<visual name = "barra">
				<pose>0 0 0.005 0 0 0</pose>
				<geometry>
					<box>
						<size>0.05 0.3 0.01</size>
					</box>
				</geometry>
				<material>
  <ambient>0.3 0.3 0.3 1</ambient>
  <emissive>0 0 0 1</emissive>
  <diffuse>0.5 0.5 0.5 1</diffuse>
  <specular>1 1 1 1</specular>
</material>

			</visual>
			<collision name = "barra">
				<pose>0 0 0.005 0 0 0</pose>
				<geometry>
					<box>
						<size>0.05 0.3 0.01</size>
					</box>
				</geometry>
			</collision>

			<visual name = "marco_0">
				<pose>0 0.125 0.035 0 0 0</pose>
				<geometry>
					<cylinder>
						<radius>0.015</radius>
						<length>0.05</length>
					</cylinder>
				</geometry>
				<material>
  <ambient>0.3 0.3 0.3 1</ambient>
  <emissive>0 0 0 1</emissive>
  <diffuse>0.5 0.5 0.5 1</diffuse>
  <specular>1 1 1 1</specular>
</material>

			</visual>
			<collision name = "marco_0">
				<pose>0 0.125 0.035 0 0 0</pose>
				<geometry>
					<cylinder>
						<radius>0.015</radius>
						<length>0.05</length>
					</cylinder>
				</geometry>
			</collision>

			<visual name = "marco_1">
				<pose>0 -0.125 0.035 0 0 0</pose>
				<geometry>
					<cylinder>
						<radius>0.015</radius>
						<length>0.05</length>
					</cylinder>
				</geometry>
				<material>
  <ambient>0.3 0.3 0.3 1</ambient>
  <emissive>0 0 0 1</emissive>
  <diffuse>0.5 0.5 0.5 1</diffuse>
  <specular>1 1 1 1</specular>
</material>

			</visual>
			<collision name = "marco_1">
				<pose>0 -0.125 0.035 0 0 0</pose>
				<geometry>
					<cylinder>
						<radius>0.015</radius>
						<length>0.05</length>
					</cylinder>
				</geometry>
			</collision>

			<inertial>
				<mass>0.1</mass>
			</inertial>
		</link>

		<link name="herramienta_0">
			<pose>0 0.125 0.11 0 0 0</pose>
			<visual name = "herramienta_0">
				<geometry>
					<cylinder>
						<radius>0.005</radius>
						<length>0.1</length>
					</cylinder>
				</geometry>
				<material>
  <ambient>0.8 0 0.8 1</ambient>
  <emissive>0 0 0 1</emissive>
  <diffuse>0.5 0.5 0.5 1</diffuse>
  <specular>1 1 1 1</specular>
</material>

			</visual>
			<collision name = "herramienta_0">
				<geometry>
					<cylinder>
						<radius>0.005</radius>
						<length>0.1</length>
					</cylinder>
				</geometry>
			</collision>
			<inertial>
				<mass>0.5</mass>
			</inertial>
		</link>
		<joint name="joint_herramienta_0" type="prismatic">
			<parent>parte_fija</parent>
			<child>herramienta_0</child>
			<axis>
				<xyz>0 1 0</xyz>
				<use_parent_model_frame>0</use_parent_model_frame>
				<limit>
				  <lower>-0.05</lower>
				  <upper>0</upper>
				  <effort>-1</effort>
				  <velocity>-1</velocity>
				</limit>
				<dynamics>
				  <spring_reference>0</spring_reference>
				  <spring_stiffness>0</spring_stiffness>
				  <damping>0</damping>
				  <friction>1</friction>
				</dynamics>
			</axis>
			<physics>
				<ode>
					<limit>
						<cfm>0</cfm>
						<erp>0.2</erp>
					</limit>
					<suspension>
						<cfm>0</cfm>
						<erp>0.2</erp>
					</suspension>
				</ode>
			</physics>
		</joint>

		<link name="herramienta_1">
			<pose>0 -0.125 0.11 0 0 0</pose>
			<visual name = "herramienta_1">
				<geometry>
					<cylinder>
						<radius>0.005</radius>
						<length>0.1</length>
					</cylinder>
				</geometry>
				<material>
  <ambient>0.8 0 0.8 1</ambient>
  <emissive>0 0 0 1</emissive>
  <diffuse>0.5 0.5 0.5 1</diffuse>
  <specular>1 1 1 1</specular>
</material>

			</visual>
			<collision name = "herramienta_1">
				<geometry>
					<cylinder>
						<radius>0.005</radius>
						<length>0.1</length>
					</cylinder>
				</geometry>
			</collision>
			<inertial>
				<mass>0.5</mass>
			</inertial>
		</link>
		<joint name="joint_herramienta_1" type="prismatic">
			<parent>parte_fija</parent>
			<child>herramienta_1</child>
			<axis>
				<xyz>0 1 0</xyz>
				<use_parent_model_frame>0</use_parent_model_frame>
				<limit>
				  <lower>-0.05</lower>
				  <upper>0</upper>
				  <effort>-1</effort>
				  <velocity>-1</velocity>
				</limit>
				<dynamics>
				  <spring_reference>0</spring_reference>
				  <spring_stiffness>0</spring_stiffness>
				  <damping>0</damping>
				  <friction>1</friction>
				</dynamics>
			</axis>
			<physics>
				<ode>
					<limit>
						<cfm>0</cfm>
						<erp>0.2</erp>
					</limit>
					<suspension>
						<cfm>0</cfm>
						<erp>0.2</erp>
					</suspension>
				</ode>
			</physics>
		</joint>


		<link name="base_pinza">
			<visual name = "cilindro_base_pinza">
				<pose>0 0 0.060000000000000005 0 0 0</pose>
				<geometry>
					<cylinder>
						<radius>0.015</radius>
						<length>0.1</length>
					</cylinder>
				</geometry>
				<material>
  <ambient>0.8 0 0.8 1</ambient>
  <emissive>0 0 0 1</emissive>
  <diffuse>0.5 0.5 0.5 1</diffuse>
  <specular>1 1 1 1</specular>
</material>

			</visual>
			<collision name = "cilindro_base_pinza">
				<pose>0 0 0.060000000000000005 0 0 0</pose>
				<geometry>
					<cylinder>
						<radius>0.015</radius>
						<length>0.1</length>
					</cylinder>
				</geometry>
			</collision>

			<visual name = "box_base_pinza">
				<pose>0 0 0.11500000000000002 0 0 0</pose>
				<geometry>
					<box>
						<size>0.10.030.01</size>
					</box>
				</geometry>
				<material>
  <ambient>0.8 0 0.8 1</ambient>
  <emissive>0 0 0 1</emissive>
  <diffuse>0.5 0.5 0.5 1</diffuse>
  <specular>1 1 1 1</specular>
</material>

			</visual>
			<collision name = "box_base_pinza">
				<pose>0 0 0.11500000000000002 0 0 0</pose>
				<geometry>
					<box>
						<size>0.10.030.01</size>
					</box>
				</geometry>
			</collision>
			<inertial>
				<mass>0.1</mass>
			</inertial>
		</link>

		<joint name="joint_base_pinza" type="fixed">
			<parent>parte_fija</parent>
			<child>base_pinza</child>
		</joint>

		<!--include>
      		<uri>model://Grapa</uri>
            <name>Grapa</name>
			<pose>0 0 0.18500000000000003 0 1.5707963267948966 0</pose>
    	</include>
    	<joint name='joint_grapa' type='fixed'>
    		<parent>base_pinza</parent>
    		<child>Grapa::superior</child>
    	</joint-->

		<link name = "dedo_0">
			<visual name = "visual_dedo_0">
				<pose>0.045000000000000005 0 0.22000000000000003 0 0 0</pose>
				<geometry>
					<box>
						<size>0.010.030.2</size>
					</box>
				</geometry>
				<material>
  <ambient>0.8 0 0.8 1</ambient>
  <emissive>0 0 0 1</emissive>
  <diffuse>0.5 0.5 0.5 1</diffuse>
  <specular>1 1 1 1</specular>
</material>

			</visual>
			<collision name = "collision_dedo_0">
				<pose>0.045000000000000005 0 0.22000000000000003 0 0 0</pose>
				<geometry>
					<box>
						<size>0.010.030.2</size>
					</box>
				</geometry>
			</collision>
			<inertial>
				<pose>0.045000000000000005 0 0.22000000000000003 0 0 0</pose>
				<mass>0.1</mass>
			</inertial>
		</link>

		<joint name="joint_dedo_0" type="prismatic">
			<parent>base_pinza</parent>
			<child>dedo_0</child>
			<pose>0.045000000000000005 0 0.12000000000000002 0 0 3.141592653589793</pose>
			<axis>
				<xyz>1 0 0</xyz>
				<use_parent_model_frame>0</use_parent_model_frame>
				<limit>
				  <lower>0.0</lower>
				  <upper>0.03</upper>
				  <effort>-1</effort>
				  <velocity>-1</velocity>
				</limit>
				<dynamics>
				  <spring_reference>0</spring_reference>
				  <spring_stiffness>0</spring_stiffness>
				  <damping>0</damping>
				  <friction>10</friction>
				</dynamics>
			</axis>
			<physics>
				<ode>
					<limit>
						<cfm>0</cfm>
						<erp>0.2</erp>
					</limit>
					<suspension>
						<cfm>0</cfm>
						<erp>0.2</erp>
					</suspension>
				</ode>
			</physics>
		</joint>


		<link name = "dedo_1">
			<visual name = "visual_dedo_1">
				<pose>-0.045000000000000005 0 0.22000000000000003 0 0 0</pose>
				<geometry>
					<box>
						<size>0.010.030.2</size>
					</box>
				</geometry>
				<material>
  <ambient>0.8 0 0.8 1</ambient>
  <emissive>0 0 0 1</emissive>
  <diffuse>0.5 0.5 0.5 1</diffuse>
  <specular>1 1 1 1</specular>
</material>

			</visual>
			<collision name = "collision_dedo_1">
				<pose>-0.045000000000000005 0 0.22000000000000003 0 0 0</pose>
				<geometry>
					<box>
						<size>0.010.030.2</size>
					</box>
				</geometry>
			</collision>
			<inertial>
				<pose>-0.045000000000000005 0 0.22000000000000003 0 0 0</pose>
				<mass>0.1</mass>
			</inertial>
		</link>

		<joint name="joint_dedo_1" type="prismatic">
			<parent>base_pinza</parent>
			<child>dedo_1</child>
			<pose>-0.045000000000000005 0 0.12000000000000002 0 0 0.0</pose>
			<axis>
				<xyz>1 0 0</xyz>
				<use_parent_model_frame>0</use_parent_model_frame>
				<limit>
				  <lower>0.0</lower>
				  <upper>0.03</upper>
				  <effort>-1</effort>
				  <velocity>-1</velocity>
				</limit>
				<dynamics>
				  <spring_reference>0</spring_reference>
				  <spring_stiffness>0</spring_stiffness>
				  <damping>0</damping>
				  <friction>10</friction>
				</dynamics>
			</axis>
			<physics>
				<ode>
					<limit>
						<cfm>0</cfm>
						<erp>0.2</erp>
					</limit>
					<suspension>
						<cfm>0</cfm>
						<erp>0.2</erp>
					</suspension>
				</ode>
			</physics>
		</joint>



  	</model>
</sdf>