<?xml version='1.0'?>
<sdf version='1.4'>
  <model name="cable_torre">
 <static>true</static>
 <link name="mesh_link">
   <pose>0 0 0 0 0 1.57</pose>
	<inertial>
    <mass>1</mass>
 	</inertial>
        <visual name="visual">
        <geometry>
            <mesh><uri>model://cable_torre/meshes/Pieza1.stl</uri>
              <scale>0.035 0.025 0.035</scale>
            </mesh>
          </geometry>
        </visual>
        <collision name="collision">
          <geometry>
            <mesh><uri>model://cable_torre/meshes/Pieza1.stl</uri>
              <scale>0.035 0.025 0.035</scale>
            </mesh>
          </geometry>
        </collision>
      </link>

      <link name="link_0">
        <pose>-8.59 0.00735 0 0 0 0</pose>
        <collision name="sphere">
          <geometry>
            <sphere>
              <radius>0.015</radius>
            </sphere>
          </geometry>
        </collision>
        <visual name="sphere">
          <geometry>
            <sphere>
              <radius>0.0175</radius>
            </sphere>
          </geometry>
          <material>
            <ambient>0 0 0 1</ambient>
            <emissive>0 0 0 1</emissive>
            <diffuse>0 0 0 1</diffuse>
            <specular>1 1 1 1</specular>
          </material>

        </visual>
      </link>

      <link name="link_1">
        <pose>8.59 -0.00735 0 0 0 0</pose>
        <collision name="sphere">
          <geometry>
            <sphere>
              <radius>0.015</radius>
            </sphere>
          </geometry>
        </collision>
        <visual name="sphere">
          <geometry>
            <sphere>
              <radius>0.0175</radius>
            </sphere>
          </geometry>
          <material>
            <ambient>0 0 0 1</ambient>
            <emissive>0 0 0 1</emissive>
            <diffuse>0 0 0 1</diffuse>
            <specular>1 1 1 1</specular>
          </material>

        </visual>
      </link>

      <joint name="world" type="fixed">
        	<child>link_0</child>
        	<parent>world</parent>
      	</joint>

        <joint name="world" type="fixed">
            <child>link_1</child>
            <parent>world</parent>
          </joint>

      <joint name="joint_1" type="universal">
          <child>mesh_link</child>
          <parent>link_0</parent>
          <axis>
              <xyz>0 1 0</xyz>
              <limit>
                <lower>-0.39269908169872414</lower>
                <upper>0.39269908169872414</upper>
              </limit>
              <dynamics>
                <friction>50</friction>
              </dynamics>
          </axis>
          <!--axis2>
              <xyz>-1 0 0</xyz>
              <limit>
                <lower>-0.7853981633974483</lower>
                <upper>0.7853981633974483</upper>
              </limit>
              <dynamics>
                <friction>50</friction>
              </dynamics>
          </axis2-->
          <physics>
              <ode>
                <cfm_damping>0</cfm_damping>
              </ode>
          </physics>
      </joint>

      <joint name="joint_2" type="universal">
          <child>mesh_link</child>
          <parent>link_1</parent>
          <axis>
              <xyz>0 1 0</xyz>
              <limit>
                <lower>-0.39269908169872414</lower>
                <upper>0.39269908169872414</upper>
              </limit>
              <dynamics>
                <friction>50</friction>
              </dynamics>
          </axis>
          <!--axis2>
              <xyz>-1 0 0</xyz>
              <limit>
                <lower>-0.7853981633974483</lower>
                <upper>0.7853981633974483</upper>
              </limit>
              <dynamics>
                <friction>50</friction>
              </dynamics>
          </axis2-->
          <physics>
              <ode>
                <cfm_damping>0</cfm_damping>
              </ode>
          </physics>
      </joint>
    </model>
</sdf>
